<?xml version="1.0" encoding="utf-8"?>
<!-- This URDF was automatically created by SolidWorks to URDF Exporter! Originally created by Stephen Brawner (brawner@gmail.com) 
     Commit Version: 1.5.0-0-g9aa0fdb  Build Version: 1.5.7004.21443
     For more information, please see http://wiki.ros.org/sw_urdf_exporter -->
<robot
  name="robot1">
  <link
    name="base_link">
    <inertial>
      <origin
        xyz="-2.8237E-06 -0.14349 0.022762"
        rpy="0 0 0" />
      <mass
        value="0.13519" />
      <inertia
        ixx="0.00046442"
        ixy="1.9998E-08"
        ixz="6.1785E-13"
        iyy="0.00014057"
        iyz="1.1305E-08"
        izz="0.00060208" />
    </inertial>
    <visual>
      <origin
        xyz="0 0 0"
        rpy="0 0 0" />
      <geometry>
        <mesh
          filename="package://robot1/meshes/base_link.STL" />
      </geometry>
      <material
        name="">
        <color
          rgba="0.027451 0.56471 0.94902 1" />
      </material>
    </visual>
    <collision>
      <origin
        xyz="0 0 0"
        rpy="0 0 0" />
      <geometry>
        <mesh
          filename="package://robot1/meshes/base_link.STL" />
      </geometry>
    </collision>
  </link>
  <link
    name="lower_plate">
    <inertial>
      <origin
        xyz="1.4955E-05 -0.0042886 0.0010033"
        rpy="0 0 0" />
      <mass
        value="0.065579" />
      <inertia
        ixx="2.6895E-05"
        ixy="-6.8281E-09"
        ixz="1.5192E-08"
        iyy="5.4185E-05"
        iyz="-7.0729E-12"
        izz="2.9579E-05" />
    </inertial>
    <visual>
      <origin
        xyz="0 0 0"
        rpy="0 0 0" />
      <geometry>
        <mesh
          filename="package://robot1/meshes/lower_plate.STL" />
      </geometry>
      <material
        name="">
        <color
          rgba="0.027451 0.56471 0.94902 1" />
      </material>
    </visual>
    <collision>
      <origin
        xyz="0 0 0"
        rpy="0 0 0" />
      <geometry>
        <mesh
          filename="package://robot1/meshes/lower_plate.STL" />
      </geometry>
    </collision>
  </link>
  <joint
    name="lower_plate"
    type="revolute">
    <origin
      xyz="0 -0.17671 0.071097"
      rpy="-1.5708 0 -1.5708" />
    <parent
      link="base_link" />
    <child
      link="lower_plate" />
    <axis
      xyz="0 0 0" />
    <limit
      lower="-3.14"
      upper="3.14"
      effort="1000"
      velocity="1" />
    <safety_controller
      k_velocity="0" />
  </joint>
  <link
    name="lower_arm">
    <inertial>
      <origin
        xyz="-0.0912958583110127 -0.0199000243229966 -0.0109155252805412"
        rpy="0 0 0" />
      <mass
        value="0.0206839694838106" />
      <inertia
        ixx="1.04050452138262E-05"
        ixy="-7.8202350463771E-14"
        ixz="-9.38773889957363E-13"
        iyy="1.58526409378008E-05"
        iyz="-1.48225634940863E-12"
        izz="7.34460089310265E-06" />
    </inertial>
    <visual>
      <origin
        xyz="0 0 0"
        rpy="0 0 0" />
      <geometry>
        <mesh
          filename="package://robot1/meshes/lower_arm.STL" />
      </geometry>
      <material
        name="">
        <color
          rgba="0.792156862745098 0.819607843137255 0.933333333333333 1" />
      </material>
    </visual>
    <collision>
      <origin
        xyz="0 0 0"
        rpy="0 0 0" />
      <geometry>
        <mesh
          filename="package://robot1/meshes/lower_arm.STL" />
      </geometry>
    </collision>
  </link>
  <joint
    name="lower_arm"
    type="revolute">
    <origin
      xyz="0.0299 0.021603 0.009624"
      rpy="-3.1416 0 1.5708" />
    <parent
      link="lower_plate" />
    <child
      link="lower_arm" />
    <axis
      xyz="0 0 0" />
    <limit
      lower="-3.14"
      upper="3.14"
      effort="1000"
      velocity="1" />
    <safety_controller
      k_velocity="0" />
  </joint>
  <link
    name="mid_arm">
    <inertial>
      <origin
        xyz="0.0307657907032864 -0.0244040039215777 0.00621653090060798"
        rpy="0 0 0" />
      <mass
        value="0.0384992712385342" />
      <inertia
        ixx="8.28530616879522E-06"
        ixy="3.4001374267329E-08"
        ixz="-8.76714848928945E-09"
        iyy="7.6534968489718E-06"
        iyz="1.2836297474616E-06"
        izz="1.2330950302944E-05" />
    </inertial>
    <visual>
      <origin
        xyz="0 0 0"
        rpy="0 0 0" />
      <geometry>
        <mesh
          filename="package://robot1/meshes/mid_arm.STL" />
      </geometry>
      <material
        name="">
        <color
          rgba="0.772549019607843 0.752941176470588 0.733333333333333 1" />
      </material>
    </visual>
    <collision>
      <origin
        xyz="0 0 0"
        rpy="0 0 0" />
      <geometry>
        <mesh
          filename="package://robot1/meshes/mid_arm.STL" />
      </geometry>
    </collision>
  </link>
  <joint
    name="mid_arm"
    type="revolute">
    <origin
      xyz="-0.1431 0.199 0.018876"
      rpy="1.8217 1.5708 0" />
    <parent
      link="lower_arm" />
    <child
      link="mid_arm" />
    <axis
      xyz="0 0 0" />
    <limit
      lower="-3.14"
      upper="3.14"
      effort="1000"
      velocity="1" />
    <safety_controller
      k_velocity="0" />
  </joint>
  <link
    name="upper_arm">
    <inertial>
      <origin
        xyz="0.0147207624528104 -0.00985048540135169 0.019754032026627"
        rpy="0 0 0" />
      <mass
        value="0.0327562013390314" />
      <inertia
        ixx="3.21681359325304E-06"
        ixy="2.14025067053605E-08"
        ixz="2.1367433093298E-08"
        iyy="6.37752706614199E-06"
        iyz="-3.78688084487857E-15"
        izz="6.37879837386873E-06" />
    </inertial>
    <visual>
      <origin
        xyz="0 0 0"
        rpy="0 0 0" />
      <geometry>
        <mesh
          filename="package://robot1/meshes/upper_arm.STL" />
      </geometry>
      <material
        name="">
        <color
          rgba="0.0980392156862745 0.0980392156862745 0.0980392156862745 1" />
      </material>
    </visual>
    <collision>
      <origin
        xyz="0 0 0"
        rpy="0 0 0" />
      <geometry>
        <mesh
          filename="package://robot1/meshes/upper_arm.STL" />
      </geometry>
    </collision>
  </link>
  <joint
    name="upper_arm"
    type="revolute">
    <origin
      xyz="0.043239 0.2011 -0.0027462"
      rpy="-1.5708 -1.3199 1.5708" />
    <parent
      link="mid_arm" />
    <child
      link="upper_arm" />
    <axis
      xyz="0 0 0" />
    <limit
      lower="-3.14"
      upper="3.14"
      effort="1000"
      velocity="1" />
    <safety_controller
      k_velocity="0" />
  </joint>
  <link
    name="gripper_plate">
    <inertial>
      <origin
        xyz="-0.000333948454849436 0.018390116414722 0.00202656983975349"
        rpy="0 0 0" />
      <mass
        value="0.0154094130606123" />
      <inertia
        ixx="2.63703384135488E-06"
        ixy="8.79424292252623E-09"
        ixz="6.37013034350629E-07"
        iyy="2.13251492759509E-06"
        iyz="-2.12648958174474E-08"
        izz="1.41990803812168E-06" />
    </inertial>
    <visual>
      <origin
        xyz="0 0 0"
        rpy="0 0 0" />
      <geometry>
        <mesh
          filename="package://robot1/meshes/gripper_plate.STL" />
      </geometry>
      <material
        name="">
        <color
          rgba="1 1 1 1" />
      </material>
    </visual>
    <collision>
      <origin
        xyz="0 0 0"
        rpy="0 0 0" />
      <geometry>
        <mesh
          filename="package://robot1/meshes/gripper_plate.STL" />
      </geometry>
    </collision>
  </link>
  <joint
    name="gripper_plate"
    type="revolute">
    <origin
      xyz="0.02002 0.5842 0.018208"
      rpy="0 0.3918 3.1416" />
    <parent
      link="upper_arm" />
    <child
      link="gripper_plate" />
    <axis
      xyz="0 0 0" />
    <limit
      lower="-3.14"
      upper="3.14"
      effort="1000"
      velocity="1" />
    <safety_controller
      k_velocity="0" />
  </joint>
  <link
    name="gripper">
    <inertial>
      <origin
        xyz="0.0292107254493458 0.000193133354860708 0.00609175559229674"
        rpy="0 0 0" />
      <mass
        value="0.0151074353317046" />
      <inertia
        ixx="1.96858209044203E-06"
        ixy="3.04757060415282E-11"
        ixz="-6.25603081049867E-07"
        iyy="2.75579911287869E-06"
        iyz="1.12400048451221E-10"
        izz="9.3454593856632E-07" />
    </inertial>
    <visual>
      <origin
        xyz="0 0 0"
        rpy="0 0 0" />
      <geometry>
        <mesh
          filename="package://robot1/meshes/gripper.STL" />
      </geometry>
      <material
        name="">
        <color
          rgba="0.298039215686275 0.298039215686275 0.298039215686275 1" />
      </material>
    </visual>
    <collision>
      <origin
        xyz="0 0 0"
        rpy="0 0 0" />
      <geometry>
        <mesh
          filename="package://robot1/meshes/gripper.STL" />
      </geometry>
    </collision>
  </link>
  <joint
    name="gripper"
    type="prismatic">
    <origin
      xyz="0.00027783 0.67959 -0.022933"
      rpy="-2.3745 -0.98821 -2.2486" />
    <parent
      link="gripper_plate" />
    <child
      link="gripper" />
    <axis
      xyz="0 0 0" />
    <limit
      lower="-3.14"
      upper="3.14"
      effort="1000"
      velocity="1" />
    <safety_controller
      k_velocity="0" />
  </joint>
</robot>